Workbook

Sheet 📊 Resumen
A1: 📊 RESUMEN FINANCIERO — CONGRESO ELECTRÓNICO 2026
A2: Este resumen se actualiza solo al modificar las hojas Gastos, Auspicios y Entradas
A4: ▶ GASTOS
A5: 💸 Total Presupuesto de Gastos | B5: ='💰 Gastos'!F60 -> 9633700
A7: ▶ INGRESOS
A8: 🎟️ Ingresos proyectados por entradas | B8: ='🎟️ Entradas'!H12 -> 1664000
A9: 🤝 Auspicios acordados (total convenios) | B9: ='🤝 Auspicios'!D25 -> 1400000
A10: 💵 Auspicios recibidos (dinero en caja) | B10: ='🤝 Auspicios'!E25 -> 1400000
A12: ▶ BALANCE Y NECESIDADES
A13: 📈 Total ingresos proyectados (entradas + auspicios acordados) | B13: ='🎟️ Entradas'!H12+'🤝 Auspicios'!D25 -> 3064000
A14: 💰 Balance neto (Ingresos proyectados − Gastos) | B14: ='🎟️ Entradas'!H12+'🤝 Auspicios'!D25-'💰 Gastos'!F60 -> -6569700
A15: 🎯 ⚠️ Monto aún necesario (solo con caja real recibida) | B15: ='💰 Gastos'!F60-'🎟️ Entradas'!H12-'🤝 Auspicios'!E25 -> 6569700
A17: ▶ COBERTURA DEL PRESUPUESTO
A18: % del presupuesto cubierto (ingresos totales / gastos) | B18: =IFERROR(('🎟️ Entradas'!H12+'🤝 Auspicios'!D25)/'💰 Gastos'!F60,0) -> 0.31805018
A19: % cubierto con dinero en caja real (auspicios recibidos + entradas) | B19: =IFERROR(('🎟️ Entradas'!H12+'🤝 Auspicios'!E25)/'💰 Gastos'!F60,0) -> 0.31805018
A21: 💡 Instrucciones: Esta hoja no se edita directamente. Ve a 💰 Gastos para ajustar el presupuesto · Ve a 🤝 Auspicios para registrar auspiciadores · Ve a 🎟️ Entradas para ajustar precios y asistentes esperados.

Sheet 💰 Gastos
A1: 🎓 CONGRESO ELECTRÓNICO 2026 — PRESUPUESTO DE GASTOS
A2: IEEE RAS UdeC · Centro de Estudiantes Ing. Civil Electrónica · Universidad de Concepción · 11–13 noviembre 2026
A3: # | B3: Categoría / Ítem de Gasto | C3: Descripción / Detalle | D3: Cantidad | E3: Costo Unitario (CLP) | F3: Total Ítem (CLP) | G3: Notas
A4: CATERING Y ALIMENTACIÓN
A5: 1 | B5: Coffee Break (días 1 y 2) | C5: Café, jugos, galletas, frutas — 2 coffee breaks/día × 2 días = 4 breaks | D5: 250 | F5: 800000 | G5: Estimado por persona, 120 asistentes promedio
A6: 2 | B6: Coffee Break (día 3 — cierre) | C6: Break especial día de clausura | D6: 250 | E6: 3000 | F6: 450000 | G6: Puede incluir algo más elaborado para el cierre
A7: 3 | B7: Almuerzo asistentes (días 2 y 3) | C7: Colación o voucher de almuerzo — 2 jornadas completas | D7: 0 | E7: 4500 | F7: =D7*E7 -> 0 | G7: Cotizar casino UdeC u opción externa
A8: 4 | B8: Catering ponentes / organizadores | C8: Almuerzo diferenciado para expositores, talleristas y comité | D8: 20 | E8: 8000 | F8: =D8*E8 -> 160000 | G8: ~15 ponentes + 5 organizadores
A9: 5 | B9: Celebración de cierre | C9: Bebidas, snacks y bocados para la actividad recreativa final | D9: 100 | E9: 3500 | F9: =D9*E9 -> 350000 | G9: Estimado 100 personas en el cierre
A10: IMPRESIÓN Y MATERIALES
A11: 6 | B11: Pendones auspiciadores — Platino (XL) | C11: Pendón 80×200 cm con logo destacado, uno por auspiciador Platino | D11: 3 | E11: 35000 | F11: =D11*E11 -> 105000 | G11: Cotizar imprenta local — pedido mínimo 3
A12: 7 | B12: Pendones auspiciadores — Oro | C12: Pendón 60×160 cm, uno por auspiciador Oro | D12: 2 | E12: 28000 | F12: =D12*E12 -> 56000
A13: 8 | B13: Pendones auspiciadores — Plata | C13: Pendón 60×160 cm, uno por auspiciador Plata | D13: 1 | E13: 28000 | F13: =D13*E13 -> 28000
A14: 9 | B14: Pendones institucionales (IEEE/UdeC/CAA) | C14: Pendones generales del evento y co-organizadores | D14: 4 | E14: 30000 | F14: =D14*E14 -> 120000 | G14: IEEE RAS, CEICE, UdeC, Congreso
A15: 10 | B15: Credenciales / fotochecks | C15: Impresión + porta-credencial. Roles: asistente, expositor, org., voluntario | D15: 250 | E15: 800 | F15: =D15*E15 -> 200000
A16: 11 | B16: Señalética del evento | C16: Indicadores de salas, stands numerados, zonas de coffee break | D16: 30 | E16: 2500 | F16: =D16*E16 -> 75000 | G16: Incluir flechas y carteles de ubicación
A17: 12 | B17: Carpetas / kits para asistentes | C17: Folder con material informativo, programa y bloc de notas | D17: 250 | E17: 2200 | F17: =D17*E17 -> 550000
A18: 13 | B18: Flyers y material de difusión (físico) | C18: Afiches para campus UdeC y otras universidades | D18: 100 | E18: 600 | F18: =D18*E18 -> 60000 | G18: Impresión A3 color
A19: 14 | B19: Diplomas — ponentes y talleristas | C19: Diploma impreso, firmado y enmarcado (opcional) | D19: 35 | E19: 1800 | F19: =D19*E19 -> 63000 | G19: ~20 ponentes + 15 talleristas
A20: 15 | B20: Diplomas — voluntarios | C20: Diploma oficial acreditación curricular para voluntarios | D20: 25 | E20: 1200 | F20: =D20*E20 -> 30000
A21: MERCHANDISING
A22: 16 | B22: Poleras equipo organizador | C22: Polera oficial del congreso para comité y voluntarios | D22: 30 | E22: 8500 | F22: =D22*E22 -> 255000 | G22: Cotizar desde 20 unidades para precio especial
A23: 17 | B23: Stickers / pins del evento | C23: Stickers con logo del congreso para asistentes | D23: 300 | E23: 300 | F23: =D23*E23 -> 90000
A24: 18 | B24: Libretas / lápices (kit asistente) | C24: Material de trabajo para asistentes — incluible en carpeta | D24: 150 | E24: 1500 | F24: =D24*E24 -> 225000
A25: PRODUCCIÓN AUDIOVISUAL
A26: 19 | B26: Arriendo sistema de sonido (si falta) | C26: Micrófono inalámbrico extra, parlantes. Verificar equipo UdeC primero | D26: 1 | E26: 80000 | F26: =D26*E26 -> 80000 | G26: Solo si el auditorio UdeC no lo provee
A27: 20 | B27: Arriendo proyector extra (salas paralelas) | C27: Proyector para salas de talleres | D27: 0 | E27: 40000 | F27: =D27*E27 -> 0 | G27: Salas paralelas pueden no tener proyector
A28: 21 | B28: Fotografía profesional (días 2 y 3) | C28: Fotógrafo para cobertura de las jornadas principales | D28: 2 | E28: 60000 | F28: =D28*E28 -> 120000 | G28: Por jornada. Considerar estudiante de periodismo
A29: 22 | B29: Transmisión / streaming (opcional) | C29: Cámara + software para transmitir algunas charlas en vivo | D29: 1 | E29: 50000 | F29: =D29*E29 -> 50000 | G29: Opcional según presupuesto disponible
A30: 23 | B30: Iluminación extra (escenario/auditorio) | C30: Luces de escenario para charlas plenarias | D30: 0 | E30: 30000 | F30: =D30*E30 -> 0 | G30: Cotizar con proveedores AV
A31: PLATAFORMA Y COMISIONES
A32: 24 | B32: Comisión plataforma de tickets (PassLine/otro) | C32: Comisión promedio ~5-8% sobre ventas brutas de entradas | D32: 0 | E32: 80000 | F32: =D32*E32 -> 0 | G32: Ajustar según proyección de ventas en hoja Entradas
A33: 25 | B33: Punto de venta físico (lector de tarjeta) | C33: Arriendo o comisión por terminal de pago para venta en puerta | D33: 0 | E33: 15000 | F33: =D33*E33 -> 0
A34: MATERIALES PARA TALLERES
A35: 26 | B35: Materiales taller de soldadura | C35: Soldadores, estaño, placas PCB, componentes | D35: 20 | E35: 11500 | F35: =D35*E35 -> 230000 | G35: Por participante — taller de ~20 personas
A36: 27 | B36: Materiales taller PCB | C36: Software (licencias o acceso), placas prototipo, insumos | D36: 0 | E36: 2000 | F36: =D36*E36 -> 0
A37: 28 | B37: Materiales taller instrumento electrónico | C37: Componentes específicos del instrumento por participante | D37: 20 | E37: 10000 | F37: =D37*E37 -> 200000 | G37: Definir según tallerista confirmado
A38: 29 | B38: Materiales talleres software (C, Matlab, LaTeX) | C38: Acceso a PC o salas de computación — costo de uso | D38: 0 | E38: 20000 | F38: =D38*E38 -> 0 | G38: Gestionar sala computación UdeC (puede ser $0)
A39: MARKETING Y DISEÑO DIGITAL
A40: 30 | B40: Diseño gráfico (externo, si aplica) | C40: Apoyo profesional para identidad visual si no lo hace el equipo | D40: 0 | E40: 0 | F40: =D40*E40 -> 0 | G40: Puede ser $0 si lo hace equipo interno
...

Sheet 🤝 Auspicios
A1: 🤝 REGISTRO DE AUSPICIADORES — CONGRESO ELECTRÓNICO 2026
A2: Agrega cada auspiciador y su monto — el Resumen se actualiza automáticamente
A3: Categorías de auspicio: 🥇 Platino = $1.000.000 🥈 Oro = $800.000 🥉 Plata = $600.000 🔵 Bronce = $400.000 🎁 Apoyo = Especie/Otro
A4: # | B4: Empresa / Organización | C4: Categoría | D4: Monto Acordado (CLP) | E4: Monto Recibido (CLP) | F4: Beneficios comprometidos | G4: Estado | H4: Observaciones
A5: 1 | B5: IEEE RAS UdeC | C5: Organizador | D5: 1400000 | E5: 1400000 | F5: Organizador | G5: Recibido | H5: Pago completo recibido
A6: 2
A7: 3
A8: 4
A9: 5
A10: 6
A11: 7
A12: 8
A13: 9
A14: 10
A15: 11
A16: 12
A17: 13
... A24: 20
A25: TOTAL AUSPICIOS ACORDADOS / RECIBIDOS | D25: =SUM(D5:D24) -> 1400000 | E25: =SUM(E5:E24) -> 1400000
A27: 💡 Instrucciones: Ingresa el nombre de la empresa, selecciona la categoría, el monto acordado en convenio y el monto efectivamente recibido. Deja en 0 el monto recibido si aún no ha llegado el pago.

Sheet 🎟️ Entradas
A1: 🎟️ PROYECCIÓN DE INGRESOS POR ENTRADAS — CONGRESO ELECTRÓNICO 2026
A2: Modifica los precios y cantidades estimadas — el total se actualiza automáticamente
A3: # | B3: Categoría de Asistente | C3: Precio P1 (CLP) | D3: Precio P2 (CLP) | E3: Precio P3 (CLP) | F3: Precio Puerta (CLP) | G3: Asistentes esperados | H3: Ingreso Proyectado (CLP)
A4: 1 | B4: Estudiante IEEE activo | C4: 7000 | D4: 9000 | E4: 12000 | F4: 15000 | G4: 30 | H4: =G4*(C4*0.3+D4*0.4+E4*0.2+F4*0.1) -> 288000
A5: 2 | B5: Estudiante mechón UdeC (1er año) | C5: 8000 | D5: 10000 | E5: 13000 | F5: 16000 | G5: 20 | H5: =G5*(C5*0.3+D5*0.4+E5*0.2+F5*0.1) -> 212000
A6: 3 | B6: Estudiante UdeC (sin membresía IEEE) | C6: 9000 | D6: 11000 | E6: 14000 | F6: 17000 | G6: 40 | H6: =G6*(C6*0.3+D6*0.4+E6*0.2+F6*0.1) -> 464000
A7: 4 | B7: Estudiante otra universidad | C7: 10000 | D7: 12000 | E7: 15000 | F7: 18000 | G7: 20 | H7: =G7*(C7*0.3+D7*0.4+E7*0.2+F7*0.1) -> 252000
A8: 5 | B8: Docente / académico | C8: 12000 | D8: 14000 | E8: 17000 | F8: 20000 | G8: 10 | H8: =G8*(C8*0.3+D8*0.4+E8*0.2+F8*0.1) -> 146000
A9: 6 | B9: Profesional del área | C9: 15000 | D9: 18000 | E9: 20000 | F9: 25000 | G9: 10 | H9: =G9*(C9*0.3+D9*0.4+E9*0.2+F9*0.1) -> 182000
A10: 7 | B10: Expositor de paper (precio fijo) | C10: 12000 | D10: 12000 | E10: 12000 | F10: 12000 | G10: 10 | H10: =G10*(C10*0.3+D10*0.4+E10*0.2+F10*0.1) -> 120000
A11: 8 | B11: Invitado / cortesía (auspiciadores) | C11: 0 | D11: 0 | E11: 0 | F11: 0 | G11: 5 | H11: =G11*(C11*0.3+D11*0.4+E11*0.2+F11*0.1) -> 0
A12: TOTAL ASISTENTES / INGRESOS PROYECTADOS POR ENTRADAS | H12: =SUM(H4:H11) -> 1664000
A14: 💡 Supuesto de mix de ventas aplicado al Ingreso Proyectado: 30% a precio Preventa 1 · 40% a Preventa 2 · 20% a Preventa 3 · 10% en Puerta. Modifica los precios y asistentes según tu estimación real.
